Workbook

Sheet Read Me
B2: YouTube Faceless AI Channel — Niche Research Tracker
B3: Data pulled 2026-08-02 from Nexlev's live YouTube channel database (50,000+ channels, semantic niche search)
B5: Goal | C5: Find faceless, AI-recreatable YouTube niches for a new channel — budget $20-70/video, US audience, editing done by freelancers.
B7: How this workbook is organized
B8: Niche Summary | C8: 10 candidate niches, aggregated stats, pulled live via formula from the Channel Tracker sheet.
B9: Channel Tracker | C9: 110 unique channels tracked across those 10 niches — the raw research data (subs, views, virality, budget fit, activity).
B10: Top Niche Picks | C10: The 5 niches that best clear every filter in your brief, with reasoning.
B11: Competitor Lists | C11: 10-15 named competitors for each of the top picks, proving the niche is both real and beatable.
B13: Screening criteria applied (from your brief)
B14: Channel size | C14: Under 100k subs, ideally 10k-50k. One-month explosions to 100k+ views are fine even on small channels.
B15: Channel age | C15: Created within the last 6 months (after 2026-02-02).
B16: Viral proof | C16: At least one video 500k+ views, and a 100k+ view baseline across recent uploads (not a one-hit wonder).
B17: Recreatable | C17: Videos under ~30 min are flagged 'Yes' — fits a $20-70 AI+freelancer budget. Longer videos cost 5x+ and are flagged accordingly.
B18: Competition proof | C18: Niche must show 15+ distinct active channels ranking for the topic — proof the format is copyable, not a one-off fluke.
B19: US audience | C19: Filtered to location = US (highest RPM, matches your ad-revenue model).
B21: Data source & caveats
B22: Source | C22: Nexlev niche-finder semantic search (AI-matched channels per topic query) + Nexlev's tracked stats snapshot per channel.
B23: Revenue figures | C23: Nexlev's own AdSense estimate — directional, not exact. Treat as a rank signal, not a guarantee.
B24: Video-length budget rule | C24: Your own note: 'hour-long videos = 5x cost'. Applied here as: <=30 min = base budget fits; >30 min = higher cost.
B25: Freshness | C25: Free-tier API quota was hit after 10 niche queries — this covers 10 well-chosen niches, not an exhaustive market scan. Re-run more queries (sports sub-niches, tech, true crime sub-formats, ASMR, etc.) once quota resets to widen the funnel further.

Sheet Channel Tracker
A1: Channel | B1: Niche(s) matched | C1: Risk category | D1: Subscribers | E1: Channel created | F1: Country | G1: Outlier score | H1: Avg views/video | I1: Median views/video | J1: Top recent video (views) | K1: # videos >=500k | L1: # videos >=100k | M1: Sample size | N1: Total videos | O1: Uploads/week | P1: Avg video length (min) | Q1: Budget fit (<=30min) | R1: Est. monthly revenue ($) | S1: Monetized? | T1: AI-made? | U1: Last upload | V1: Days since last upload | W1: Active? (<=45d) | X1: Meets viral bar?
A2: SIMSKY BOSSKY | B2: motivational success stories; psychology and human behavior facts; space facts and astronomy explained | C2: Low risk / steady | D2: 89900 | E2: 2026-03-27 | F2: US | G2: 16.41 | H2: 1680737 | I2: 312953 | J2: 281000 | K2: 0 | L2: 1 | M2: 3 | N2: 77 | O2: 1.75 | P2: 0.7 | Q2: =IF(P2="","",IF(P2<=30,"Yes","No - 5x+ cost")) -> Yes | R2: 79.33 | S2: Yes | T2: No | U2: 2026-07-09 | V2: 24 | W2: =IF(V2="","Unknown",IF(V2<=45,"Active","Stale")) -> Active | X2: =IF(AND(K2>=1,M2>0,L2/M2>=0.6,D2<100000),"YES","no") -> no
A3: Hidden Planet Docs | B3: ancient civilizations and archaeology mysteries; history documentary deep dive; space facts and astronomy explained; unsolved mysteries and paranormal | C3: Low risk / steady/Medium risk | D3: 73300 | E3: 2026-02-22 | F3: US | G3: 2.78 | H3: 126514 | I3: 53037 | J3: 862000 | K3: 4 | L3: 5 | M3: 5 | N3: 75 | O3: 3.5 | P3: 30.4 | Q3: =IF(P3="","",IF(P3<=30,"Yes","No - 5x+ cost")) -> No - 5x+ cost | R3: 12332.77 | S3: Yes | T3: Yes | U3: 2026-07-29 | V3: 4 | W3: =IF(V3="","Unknown",IF(V3<=45,"Active","Stale")) -> Active | X3: =IF(AND(K3>=1,M3>0,L3/M3>=0.6,D3<100000),"YES","no") -> YES
A4: Axen | B4: ancient civilizations and archaeology mysteries; psychology and human behavior facts | C4: Low risk / steady | D4: 49200 | E4: 2026-04-28 | F4: US | G4: 2.66 | H4: 461753 | I4: 25819 | J4: 3000000 | K4: 3 | L4: 4 | M4: 5 | N4: 11 | O4: 0 | P4: 7.9 | Q4: =IF(P4="","",IF(P4<=30,"Yes","No - 5x+ cost")) -> Yes | R4: 0 | S4: No | T4: Yes | U4: 2026-06-26 | V4: 37 | W4: =IF(V4="","Unknown",IF(V4<=45,"Active","Stale")) -> Active | X4: =IF(AND(K4>=1,M4>0,L4/M4>=0.6,D4<100000),"YES","no") -> YES
A5: DungeonsNoWork | B5: reddit relationship stories AITA | C5: Medium risk | D5: 37700 | E5: 2026-05-15 | F5: US | G5: 8.65 | H5: 85838 | I5: 84045 | J5: 140000 | K5: 0 | L5: 3 | M5: 5 | N5: 9 | O5: 1 | P5: 22.3 | Q5: =IF(P5="","",IF(P5<=30,"Yes","No - 5x+ cost")) -> Yes | R5: 819.11 | S5: Yes | T5: No | U5: 2026-07-24 | V5: 9 | W5: =IF(V5="","Unknown",IF(V5<=45,"Active","Stale")) -> Active | X5: =IF(AND(K5>=1,M5>0,L5/M5>=0.6,D5<100000),"YES","no") -> no
A6: PlanetCam | B6: space facts and astronomy explained | C6: Low risk / steady | D6: 36400 | E6: 2026-03-16 | F6: US | G6: 2.7 | H6: 962440 | I6: 26190 | J6: 405000 | K6: 0 | L6: 1 | M6: 3 | N6: 28 | O6: 0 | P6: 0.9 | Q6: =IF(P6="","",IF(P6<=30,"Yes","No - 5x+ cost")) -> Yes | R6: 0 | S6: No | T6: Yes | U6: 2026-05-20 | V6: 74 | W6: =IF(V6="","Unknown",IF(V6<=45,"Active","Stale")) -> Stale | X6: =IF(AND(K6>=1,M6>0,L6/M6>=0.6,D6<100000),"YES","no") -> no
A7: Immersive Bible Stories | B7: ancient civilizations and archaeology mysteries; history documentary deep dive | C7: Low risk / steady | D7: 35800 | E7: 2026-04-15 | F7: US | G7: 10.12 | H7: 116583 | I7: 98351 | J7: 371000 | K7: 0 | L7: 5 | M7: 5 | N7: 17 | O7: 0 | P7: 71.4 | Q7: =IF(P7="","",IF(P7<=30,"Yes","No - 5x+ cost")) -> No - 5x+ cost | R7: 0 | S7: No | T7: Yes | U7: 2026-05-07 | V7: 87 | W7: =IF(V7="","Unknown",IF(V7<=45,"Active","Stale")) -> Stale | X7: =IF(AND(K7>=1,M7>0,L7/M7>=0.6,D7<100000),"YES","no") -> no
A8: Silas Recap | B8: motivational success stories; reddit relationship stories AITA; sports highlights and recap | C8: High risk / fast/Low risk / steady/Medium risk | D8: 34100 | E8: 2026-02-11 | F8: US | G8: 16.14 | H8: 211880 | I8: 157292 | J8: 758000 | K8: 1 | L8: 5 | M8: 5 | N8: 23 | O8: 0 | P8: 86.3 | Q8: =IF(P8="","",IF(P8<=30,"Yes","No - 5x+ cost")) -> No - 5x+ cost | R8: 0 | S8: No | T8: Yes | U8: 2026-04-15 | V8: 109 | W8: =IF(V8="","Unknown",IF(V8<=45,"Active","Stale")) -> Stale | X8: =IF(AND(K8>=1,M8>0,L8/M8>=0.6,D8<100000),"YES","no") -> YES
A9: Markets of the Past | B9: history documentary deep dive; psychology and human behavior facts | C9: Low risk / steady | D9: 33100 | E9: 2026-04-10 | F9: US | G9: 2.21 | H9: 59401 | I9: 21440 | J9: 376000 | K9: 0 | L9: 4 | M9: 5 | N9: 22 | O9: 4 | P9: 30.2 | Q9: =IF(P9="","",IF(P9<=30,"Yes","No - 5x+ cost")) -> No - 5x+ cost | R9: 5324.11 | S9: Yes | T9: Yes | U9: 2026-07-29 | V9: 4 | W9: =IF(V9="","Unknown",IF(V9<=45,"Active","Stale")) -> Active | X9: =IF(AND(K9>=1,M9>0,L9/M9>=0.6,D9<100000),"YES","no") -> no
A10: Your Verdict HQ | B10: celebrity news and gossip drama; reddit relationship stories AITA; true crime case files | C10: High risk / fast/Medium risk | D10: 32200 | E10: 2026-02-26 | F10: US | G10: 34.45 | H10: 536583 | I10: 334702 | J10: 22000 | K10: 0 | L10: 0 | M10: 2 | N10: 94 | O10: 5.5 | P10: 1 | Q10: =IF(P10="","",IF(P10<=30,"Yes","No - 5x+ cost")) -> Yes | R10: 22.28 | S10: Yes | T10: Yes | U10: 2026-07-29 | V10: 4 | W10: =IF(V10="","Unknown",IF(V10<=45,"Active","Stale")) -> Active | X10: =IF(AND(K10>=1,M10>0,L10/M10>=0.6,D10<100000),"YES","no") -> no
A11: The Understory | B11: space facts and astronomy explained | C11: Low risk / steady | D11: 30400 | E11: 2026-04-28 | F11: US | G11: 3.53 | H11: 114539 | I11: 34315 | J11: 575000 | K11: 1 | L11: 5 | M11: 5 | N11: 29 | O11: 1 | P11: 9.6 | Q11: =IF(P11="","",IF(P11<=30,"Yes","No - 5x+ cost")) -> Yes | R11: 3510.47 | S11: Yes | T11: No | U11: 2026-07-23 | V11: 10 | W11: =IF(V11="","Unknown",IF(V11<=45,"Active","Stale")) -> Active | X11: =IF(AND(K11>=1,M11>0,L11/M11>=0.6,D11<100000),"YES","no") -> YES
A12: Weirdium | B12: ancient civilizations and archaeology mysteries; history documentary deep dive; psychology and human behavior facts; unsolved mysteries and paranormal | C12: Low risk / steady/Medium risk | D12: 29200 | E12: 2026-02-22 | F12: US | G12: 16.95 | H12: 329336 | I12: 164636 | J12: 1300000 | K12: 5 | L12: 5 | M12: 5 | N12: 18 | O12: 0 | P12: 36.3 | Q12: =IF(P12="","",IF(P12<=30,"Yes","No - 5x+ cost")) -> No - 5x+ cost | R12: 0 | S12: No | T12: No | U12: 2026-06-14 | V12: 49 | W12: =IF(V12="","Unknown",IF(V12<=45,"Active","Stale")) -> Stale | X12: =IF(AND(K12>=1,M12>0,L12/M12>=0.6,D12<100000),"YES","no") -> YES
A13: Inside Japan Living | B13: psychology and human behavior facts | C13: Low risk / steady | D13: 25700 | E13: 2026-05-07 | F13: US | G13: 2.77 | H13: 81210 | I13: 26918 | J13: 807000 | K13: 1 | L13: 4 | M13: 5 | N13: 24 | O13: 2.5 | P13: 21.5 | Q13: =IF(P13="","",IF(P13<=30,"Yes","No - 5x+ cost")) -> Yes | R13: 3349.9 | S13: Yes | T13: Yes | U13: 2026-07-29 | V13: 4 | W13: =IF(V13="","Unknown",IF(V13<=45,"Active","Stale")) -> Active | X13: =IF(AND(K13>=1,M13>0,L13/M13>=0.6,D13<100000),"YES","no") -> YES
... A111: Financial Education After 50 | B111: motivational success stories | C111: Low risk / steady | D111: 1040 | E111: 2026-02-22 | F111: US | G111: 3.29 | H111: 54292 | I111: 12557 | J111: 456000 | K111: 0 | L111: 5 | M111: 5 | N111: 47 | O111: 1.75 | P111: 2.2 | Q111: =IF(P111="","",IF(P111<=30,"Yes","No - 5x+ cost")) -> Yes | R111: 0 | S111: No | T111: No | U111: 2026-07-26 | V111: 7 | W111: =IF(V111="","Unknown",IF(V111<=45,"Active","Stale")) -> Active | X111: =IF(AND(K111>=1,M111>0,L111/M111>=0.6,D111<100000),"YES","no") -> no

Sheet Niche Summary
A1: Niche | B1: Risk category | C1: # channels found | D1: # meeting viral bar | E1: Avg subscribers | F1: Avg views/video | G1: Max top-video views | H1: # with 500k+ video | I1: Avg video length (min) | J1: # active (<=45d) | K1: Verdict
A2: Space Facts And Astronomy Explained | B2: Low risk / steady | C2: =COUNTIF('Channel Tracker'!$B$2:$B$111,"*"&$A2&"*") -> 20 | D2: =SUMPRODUCT(('Channel Tracker'!$X$2:$X$111="YES")*ISNUMBER(SEARCH($A2,'Channel Tracker'!$B$2:$B$111))) -> 4 | E2: =IFERROR(AVERAGEIF('Channel Tracker'!$B$2:$B$111,"*"&$A2&"*",'Channel Tracker'!$D$2:$D$111),0) -> 17184.5 | F2: =IFERROR(AVERAGEIF('Channel Tracker'!$B$2:$B$111,"*"&$A2&"*",'Channel Tracker'!$H$2:$H$111),0) -> 208394.15 | G2: =IFERROR(_xlfn.MAXIFS('Channel Tracker'!$J$2:$J$111,'Channel Tracker'!$B$2:$B$111,"*"&$A2&"*"),0) -> 1300000 | H2: =SUMPRODUCT(('Channel Tracker'!$K$2:$K$111>=1)*ISNUMBER(SEARCH($A2,'Channel Tracker'!$B$2:$B$111))) -> 4 | I2: =IFERROR(AVERAGEIF('Channel Tracker'!$B$2:$B$111,"*"&$A2&"*",'Channel Tracker'!$P$2:$P$111),0) -> 14.125 | J2: =SUMPRODUCT(('Channel Tracker'!$W$2:$W$111="Active")*ISNUMBER(SEARCH($A2,'Channel Tracker'!$B$2:$B$111))) -> 14 | K2: STRONG — multiple sub-10-min explainer channels breaking 500k-1.3M views within months of launch; several still unmonetized (whitespace).
A3: History Documentary Deep Dive | B3: Low risk / steady | C3: =COUNTIF('Channel Tracker'!$B$2:$B$111,"*"&$A3&"*") -> 20 | D3: =SUMPRODUCT(('Channel Tracker'!$X$2:$X$111="YES")*ISNUMBER(SEARCH($A3,'Channel Tracker'!$B$2:$B$111))) -> 4 | E3: =IFERROR(AVERAGEIF('Channel Tracker'!$B$2:$B$111,"*"&$A3&"*",'Channel Tracker'!$D$2:$D$111),0) -> 13193 | F3: =IFERROR(AVERAGEIF('Channel Tracker'!$B$2:$B$111,"*"&$A3&"*",'Channel Tracker'!$H$2:$H$111),0) -> 91478.8 | G3: =IFERROR(_xlfn.MAXIFS('Channel Tracker'!$J$2:$J$111,'Channel Tracker'!$B$2:$B$111,"*"&$A3&"*"),0) -> 1300000 | H3: =SUMPRODUCT(('Channel Tracker'!$K$2:$K$111>=1)*ISNUMBER(SEARCH($A3,'Channel Tracker'!$B$2:$B$111))) -> 5 | I3: =IFERROR(AVERAGEIF('Channel Tracker'!$B$2:$B$111,"*"&$A3&"*",'Channel Tracker'!$P$2:$P$111),0) -> 29.85 | J3: =SUMPRODUCT(('Channel Tracker'!$W$2:$W$111="Active")*ISNUMBER(SEARCH($A3,'Channel Tracker'!$B$2:$B$111))) -> 15 | K3: MIXED — great virality but many winners run 30-70min (5x+ budget). Stick to short-format history sub-niches only.
A4: True Crime Case Files | B4: Medium risk | C4: =COUNTIF('Channel Tracker'!$B$2:$B$111,"*"&$A4&"*") -> 20 | D4: =SUMPRODUCT(('Channel Tracker'!$X$2:$X$111="YES")*ISNUMBER(SEARCH($A4,'Channel Tracker'!$B$2:$B$111))) -> 4 | E4: =IFERROR(AVERAGEIF('Channel Tracker'!$B$2:$B$111,"*"&$A4&"*",'Channel Tracker'!$D$2:$D$111),0) -> 7601.45 | F4: =IFERROR(AVERAGEIF('Channel Tracker'!$B$2:$B$111,"*"&$A4&"*",'Channel Tracker'!$H$2:$H$111),0) -> 79646.75 | G4: =IFERROR(_xlfn.MAXIFS('Channel Tracker'!$J$2:$J$111,'Channel Tracker'!$B$2:$B$111,"*"&$A4&"*"),0) -> 830000 | H4: =SUMPRODUCT(('Channel Tracker'!$K$2:$K$111>=1)*ISNUMBER(SEARCH($A4,'Channel Tracker'!$B$2:$B$111))) -> 4 | I4: =IFERROR(AVERAGEIF('Channel Tracker'!$B$2:$B$111,"*"&$A4&"*",'Channel Tracker'!$P$2:$P$111),0) -> 36.27 | J4: =SUMPRODUCT(('Channel Tracker'!$W$2:$W$111="Active")*ISNUMBER(SEARCH($A4,'Channel Tracker'!$B$2:$B$111))) -> 17 | K4: STRONG but crowded — deep competitor pool, proves demand; favor shorter (10-15min) sub-formats to hit budget.
A5: Reddit Relationship Stories Aita | B5: Medium risk | C5: =COUNTIF('Channel Tracker'!$B$2:$B$111,"*"&$A5&"*") -> 20 | D5: =SUMPRODUCT(('Channel Tracker'!$X$2:$X$111="YES")*ISNUMBER(SEARCH($A5,'Channel Tracker'!$B$2:$B$111))) -> 1 | E5: =IFERROR(AVERAGEIF('Channel Tracker'!$B$2:$B$111,"*"&$A5&"*",'Channel Tracker'!$D$2:$D$111),0) -> 10790 | F5: =IFERROR(AVERAGEIF('Channel Tracker'!$B$2:$B$111,"*"&$A5&"*",'Channel Tracker'!$H$2:$H$111),0) -> 80187.15 | G5: =IFERROR(_xlfn.MAXIFS('Channel Tracker'!$J$2:$J$111,'Channel Tracker'!$B$2:$B$111,"*"&$A5&"*"),0) -> 758000 | H5: =SUMPRODUCT(('Channel Tracker'!$K$2:$K$111>=1)*ISNUMBER(SEARCH($A5,'Channel Tracker'!$B$2:$B$111))) -> 1 | I5: =IFERROR(AVERAGEIF('Channel Tracker'!$B$2:$B$111,"*"&$A5&"*",'Channel Tracker'!$P$2:$P$111),0) -> 38.315 | J5: =SUMPRODUCT(('Channel Tracker'!$W$2:$W$111="Active")*ISNUMBER(SEARCH($A5,'Channel Tracker'!$B$2:$B$111))) -> 16 | K5: GOOD — very hot right now (several May-June 2026 launches already breaking out); moderate length.
A6: Psychology And Human Behavior Facts | B6: Low risk / steady | C6: =COUNTIF('Channel Tracker'!$B$2:$B$111,"*"&$A6&"*") -> 20 | D6: =SUMPRODUCT(('Channel Tracker'!$X$2:$X$111="YES")*ISNUMBER(SEARCH($A6,'Channel Tracker'!$B$2:$B$111))) -> 6 | E6: =IFERROR(AVERAGEIF('Channel Tracker'!$B$2:$B$111,"*"&$A6&"*",'Channel Tracker'!$D$2:$D$111),0) -> 17214.5 | F6: =IFERROR(AVERAGEIF('Channel Tracker'!$B$2:$B$111,"*"&$A6&"*",'Channel Tracker'!$H$2:$H$111),0) -> 191771.1 | G6: =IFERROR(_xlfn.MAXIFS('Channel Tracker'!$J$2:$J$111,'Channel Tracker'!$B$2:$B$111,"*"&$A6&"*"),0) -> 3000000 | H6: =SUMPRODUCT(('Channel Tracker'!$K$2:$K$111>=1)*ISNUMBER(SEARCH($A6,'Channel Tracker'!$B$2:$B$111))) -> 7 | I6: =IFERROR(AVERAGEIF('Channel Tracker'!$B$2:$B$111,"*"&$A6&"*",'Channel Tracker'!$P$2:$P$111),0) -> 22.14 | J6: =SUMPRODUCT(('Channel Tracker'!$W$2:$W$111="Active")*ISNUMBER(SEARCH($A6,'Channel Tracker'!$B$2:$B$111))) -> 17 | K6: STRONG — short format (8-15min), one channel hit 3M views unmonetized; high recreatability.
A7: Ancient Civilizations And Archaeology Mysteries | B7: Low risk / steady | C7: =COUNTIF('Channel Tracker'!$B$2:$B$111,"*"&$A7&"*") -> 20 | D7: =SUMPRODUCT(('Channel Tracker'!$X$2:$X$111="YES")*ISNUMBER(SEARCH($A7,'Channel Tracker'!$B$2:$B$111))) -> 6 | E7: =IFERROR(AVERAGEIF('Channel Tracker'!$B$2:$B$111,"*"&$A7&"*",'Channel Tracker'!$D$2:$D$111),0) -> 14957 | F7: =IFERROR(AVERAGEIF('Channel Tracker'!$B$2:$B$111,"*"&$A7&"*",'Channel Tracker'!$H$2:$H$111),0) -> 123555.2 | G7: =IFERROR(_xlfn.MAXIFS('Channel Tracker'!$J$2:$J$111,'Channel Tracker'!$B$2:$B$111,"*"&$A7&"*"),0) -> 3100000 | H7: =SUMPRODUCT(('Channel Tracker'!$K$2:$K$111>=1)*ISNUMBER(SEARCH($A7,'Channel Tracker'!$B$2:$B$111))) -> 7 | I7: =IFERROR(AVERAGEIF('Channel Tracker'!$B$2:$B$111,"*"&$A7&"*",'Channel Tracker'!$P$2:$P$111),0) -> 24.745 | J7: =SUMPRODUCT(('Channel Tracker'!$W$2:$W$111="Active")*ISNUMBER(SEARCH($A7,'Channel Tracker'!$B$2:$B$111))) -> 12 | K7: STRONG — one breakout short-doc format (3min!) hit 3.1M views unmonetized; cheap to produce.
A8: Unsolved Mysteries And Paranormal | B8: Medium risk | C8: =COUNTIF('Channel Tracker'!$B$2:$B$111,"*"&$A8&"*") -> 20 | D8: =SUMPRODUCT(('Channel Tracker'!$X$2:$X$111="YES")*ISNUMBER(SEARCH($A8,'Channel Tracker'!$B$2:$B$111))) -> 4 | E8: =IFERROR(AVERAGEIF('Channel Tracker'!$B$2:$B$111,"*"&$A8&"*",'Channel Tracker'!$D$2:$D$111),0) -> 9700.45 | F8: =IFERROR(AVERAGEIF('Channel Tracker'!$B$2:$B$111,"*"&$A8&"*",'Channel Tracker'!$H$2:$H$111),0) -> 78666.25 | G8: =IFERROR(_xlfn.MAXIFS('Channel Tracker'!$J$2:$J$111,'Channel Tracker'!$B$2:$B$111,"*"&$A8&"*"),0) -> 1300000 | H8: =SUMPRODUCT(('Channel Tracker'!$K$2:$K$111>=1)*ISNUMBER(SEARCH($A8,'Channel Tracker'!$B$2:$B$111))) -> 4 | I8: =IFERROR(AVERAGEIF('Channel Tracker'!$B$2:$B$111,"*"&$A8&"*",'Channel Tracker'!$P$2:$P$111),0) -> 37.725 | J8: =SUMPRODUCT(('Channel Tracker'!$W$2:$W$111="Active")*ISNUMBER(SEARCH($A8,'Channel Tracker'!$B$2:$B$111))) -> 15 | K8: PROMISING but thin sample — one channel is a huge outlier (69.75 score) days-old; needs more competitor validation.
A9: Motivational Success Stories | B9: Low risk / steady | C9: =COUNTIF('Channel Tracker'!$B$2:$B$111,"*"&$A9&"*") -> 20 | D9: =SUMPRODUCT(('Channel Tracker'!$X$2:$X$111="YES")*ISNUMBER(SEARCH($A9,'Channel Tracker'!$B$2:$B$111))) -> 3 | E9: =IFERROR(AVERAGEIF('Channel Tracker'!$B$2:$B$111,"*"&$A9&"*",'Channel Tracker'!$D$2:$D$111),0) -> 11664.5 | F9: =IFERROR(AVERAGEIF('Channel Tracker'!$B$2:$B$111,"*"&$A9&"*",'Channel Tracker'!$H$2:$H$111),0) -> 163272.25 | G9: =IFERROR(_xlfn.MAXIFS('Channel Tracker'!$J$2:$J$111,'Channel Tracker'!$B$2:$B$111,"*"&$A9&"*"),0) -> 848000 | H9: =SUMPRODUCT(('Channel Tracker'!$K$2:$K$111>=1)*ISNUMBER(SEARCH($A9,'Channel Tracker'!$B$2:$B$111))) -> 3 | I9: =IFERROR(AVERAGEIF('Channel Tracker'!$B$2:$B$111,"*"&$A9&"*",'Channel Tracker'!$P$2:$P$111),0) -> 28.97 | J9: =SUMPRODUCT(('Channel Tracker'!$W$2:$W$111="Active")*ISNUMBER(SEARCH($A9,'Channel Tracker'!$B$2:$B$111))) -> 15 | K9: GOOD — several short/cheap formats with 500k-848k view hits; steady evergreen demand.
A10: Celebrity News And Gossip Drama | B10: High risk / fast | C10: =COUNTIF('Channel Tracker'!$B$2:$B$111,"*"&$A10&"*") -> 20 | D10: =SUMPRODUCT(('Channel Tracker'!$X$2:$X$111="YES")*ISNUMBER(SEARCH($A10,'Channel Tracker'!$B$2:$B$111))) -> 5 | E10: =IFERROR(AVERAGEIF('Channel Tracker'!$B$2:$B$111,"*"&$A10&"*",'Channel Tracker'!$D$2:$D$111),0) -> 4987.5 | F10: =IFERROR(AVERAGEIF('Channel Tracker'!$B$2:$B$111,"*"&$A10&"*",'Channel Tracker'!$H$2:$H$111),0) -> 99618.7 | G10: =IFERROR(_xlfn.MAXIFS('Channel Tracker'!$J$2:$J$111,'Channel Tracker'!$B$2:$B$111,"*"&$A10&"*"),0) -> 1500000 | H10: =SUMPRODUCT(('Channel Tracker'!$K$2:$K$111>=1)*ISNUMBER(SEARCH($A10,'Channel Tracker'!$B$2:$B$111))) -> 6 | I10: =IFERROR(AVERAGEIF('Channel Tracker'!$B$2:$B$111,"*"&$A10&"*",'Channel Tracker'!$P$2:$P$111),0) -> 25.495 | J10: =SUMPRODUCT(('Channel Tracker'!$W$2:$W$111="Active")*ISNUMBER(SEARCH($A10,'Channel Tracker'!$B$2:$B$111))) -> 16 | K10: STRONG (high risk/fast) — proven $12k/mo revenue channel, several sub-8-month channels breaking 500k-1.5M.
A11: Sports Highlights And Recap | B11: High risk / fast | C11: =COUNTIF('Channel Tracker'!$B$2:$B$111,"*"&$A11&"*") -> 20 | D11: =SUMPRODUCT(('Channel Tracker'!$X$2:$X$111="YES")*ISNUMBER(SEARCH($A11,'Channel Tracker'!$B$2:$B$111))) -> 8 | E11: =IFERROR(AVERAGEIF('Channel Tracker'!$B$2:$B$111,"*"&$A11&"*",'Channel Tracker'!$D$2:$D$111),0) -> 8552 | F11: =IFERROR(AVERAGEIF('Channel Tracker'!$B$2:$B$111,"*"&$A11&"*",'Channel Tracker'!$H$2:$H$111),0) -> 138929.75 | G11: =IFERROR(_xlfn.MAXIFS('Channel Tracker'!$J$2:$J$111,'Channel Tracker'!$B$2:$B$111,"*"&$A11&"*"),0) -> 2400000 | H11: =SUMPRODUCT(('Channel Tracker'!$K$2:$K$111>=1)*ISNUMBER(SEARCH($A11,'Channel Tracker'!$B$2:$B$111))) -> 9 | I11: =IFERROR(AVERAGEIF('Channel Tracker'!$B$2:$B$111,"*"&$A11&"*",'Channel Tracker'!$P$2:$P$111),0) -> 26.57 | J11: =SUMPRODUCT(('Channel Tracker'!$W$2:$W$111="Active")*ISNUMBER(SEARCH($A11,'Channel Tracker'!$B$2:$B$111))) -> 13 | K11: STRONG (high risk/fast) — cheap short recap format hit 2.4M views; fast news cycle = fast content decay too.

Sheet Top Niche Picks
B2: Top 5 Niche Picks
B3: Ranked by fit against your full brief: virality, size, age, recreatability, budget, competitor depth.
A5: Rank | B5: Niche | C5: Risk category | D5: Why it clears your filters | E5: Example seed channel | F5: Recreatable with AI + freelancer?
A6: 1 | B6: Space Facts & Astronomy Explainers | C6: Low risk / steady | D6: Best-fit niche in this scan. Multiple channels launched Feb-Jun 2026 already breaking 500k-1.3M views on 8-11 min videos — well inside a $20-70 AI+freelancer budget. 'Bluntly Explained' (21.4k subs, outlier 13.35x) and 'Hidden Planet Docs' ($12.3k/mo, 4 videos over 500k) prove both the format and the monetization. Several strong channels (PlanetCam, The Geo Bytes) aren't even monetized yet — that's your entry window. | E6: Bluntly Explained — 21.4k subs, created 2026-04-14, 3 videos 500k+, avg 9.5min/video | F6: Yes — AI narration + stock/animated space footage + freelance edit fits budget easily.
A7: 2 | B7: Psychology & Human Behavior Facts | C7: Low risk / steady | D7: Short format (8-15min) with outsized breakout potential — 'Axen' hit 3M views on a single video (471s avg length) while still unmonetized. 'Money Simplified' and 'Inside Japan Living' show the format generalizes across adjacent sub-topics (finance psychology, culture facts), meaning you have room to pivot without starting over. | E7: Axen — 49.2k subs, created 2026-04-28, one video at 3,000,000 views, avg 8min/video | F7: Yes — talking-point script + AI voiceover + stock/motion-graphic B-roll, short runtime.
A8: 3 | B8: Ancient Civilizations & Archaeology (short-doc format) | C8: Low risk / steady | D8: The standout here is format, not just topic: 'Wildcrafted Homes' hit 3.1M views on a 3-minute video and is still unmonetized. That's the cheapest possible production (short script, few AI clips) paired with the highest view-to-cost ratio in the whole scan. Evergreen topic, no news-cycle risk, works for years. | E8: Wildcrafted Homes — 17.4k subs, created 2026-02-11, one video at 3,100,000 views, avg 3min/video | F8: Yes — extremely cheap: short AI-narrated clips, minimal editing complexity.
A9: 4 | B9: Celebrity News / Recap Drama (high risk, fast payoff) | C9: High risk / fast | D9: If you want faster (if less stable) results: 'Unfiltered Influence' proves the ceiling — $12.4k/mo, 5.5k subs, 5-of-5 recent videos over 100k views, 2 videos over 500k, on a 6-month-old channel. Deep competitor bench (Star Bluks, Best Choice Recaps, Crown Recaps, Daily Recaps) confirms the format is copyable, not a fluke — but content needs constant refresh and is more exposed to platform/legal risk (name/likeness) than the evergreen picks. | E9: Unfiltered Influence — 5.5k subs, created 2026-02-12, $12,427/mo, 2 videos 500k+ | F9: Yes, but needs a steady news-scanning workflow (freelancer or you) to keep scripts current.
A10: 5 | B10: Sports Highlights & Recap (high risk, fast payoff) | C10: High risk / fast | D10: 'Boxing Vibe' hit 2.4M views on a 6.4-minute video with only 2.9k subscribers — proof a brand new, small channel can catch a single fight/event and break out fast. Trade-off: sports content decays fast and needs to ride a live news cycle, so output cadence matters more than in the evergreen picks above. | E10: Boxing Vibe — 2.9k subs, created 2026-04-16, one video at 2,400,000 views, avg 6.4min/video | F10: Yes for recap/highlight format — stock footage + AI commentary, short runtime.
B13: Also validated, but flagged (see Niche Summary tab for detail):
B14: • True Crime Case Files — deepest competitor pool of the whole scan (15+ active channels), but most winning videos run 20-40min. Only pursue with a sub-15min format (e.g. 'Verdictly' style) to stay in budget.
B15: • Reddit Relationship Stories (AITA) — very hot right now (multiple May/June 2026 launches already breaking 100k+), but typical run length is long (40-90min); needs a short-format angle to fit budget.
B16: • Unsolved Mysteries / Paranormal — one channel ('Impossible Places Global') is an extreme outlier at 2 months old, but the sample size here is thin (3 channels found on this query) — re-query before committing.

Sheet Competitor Lists
B2: Competitor Lists — Top 5 Picks
B3: 10-15 named, currently-active competitors per niche, sorted by outlier score (highest = strongest breakout). Proof the niche is beatable, not a one-channel fluke.
B5: Space Facts & Astronomy Explainers
B6: Channel | C6: Subscribers | D6: Created | E6: Outlier score | F6: Avg views/video | G6: Top video (views) | H6: Videos >=500k | I6: Monetized?
B7: Reddit Unseen Planet | C7: 2500 | D7: 2026-04-01 | E7: 44.98 | F7: 171454 | G7: 191000 | H7: 0 | I7: Yes
B8: SIMSKY BOSSKY | C8: 89900 | D8: 2026-03-27 | E8: 16.41 | F8: 1680737 | G8: 281000 | H8: 0 | I8: Yes
B9: Bluntly Explained | C9: 21400 | D9: 2026-04-14 | E9: 13.35 | F9: 269166 | G9: 1300000 | H9: 3 | I9: Yes
B10: Causality | C10: 17300 | D10: 2026-05-15 | E10: 9.47 | F10: 219269 | G10: 881000 | H10: 1 | I10: Yes
B11: Velkar Abyss Archive | C11: 5340 | D11: 2026-03-10 | E11: 9.24 | F11: 123052 | G11: 231000 | H11: 0 | I11: Yes
B12: Animated Military | C12: 10600 | D12: 2026-04-05 | E12: 7.32 | F12: 117407 | G12: 372000 | H12: 0 | I12: Yes
B13: True Planet | C13: 2360 | D13: 2026-06-01 | E13: 5.32 | F13: 28792 | G13: 109000 | H13: 0 | I13: No
B14: Humanity Timeline | C14: 3290 | D14: 2026-05-21 | E14: 5.26 | F14: 46980 | G14: 197000 | H14: 0 | I14: Yes
B15: WarpTube | C15: 1130 | D15: 2026-02-17 | E15: 4.8 | F15: 19155 | G15: 36000 | H15: 0 | I15: No
B16: Historeelz | C16: 8070 | D16: 2026-05-20 | E16: 4.56 | F16: 28392 | G16: 19000 | H16: 0 | I16: No
B17: The Net Explainer | C17: 6010 | D17: 2026-04-09 | E17: 4.4 | F17: 56209 | G17: 224000 | H17: 0 | I17: Yes
B18: Cinema Explanation | C18: 2850 | D18: 2026-05-22 | E18: 3.78 | F18: 14249 | G18: 43000 | H18: 0 | I18: No
... B21: Ceph Explain | C21: 1320 | D21: 2026-04-06 | E21: 3.26 | F21: 27270 | G21: 97000 | H21: 0 | I21: Yes
B24: Psychology & Human Behavior Facts
B25: Channel | C25: Subscribers | D25: Created | E25: Outlier score | F25: Avg views/video | G25: Top video (views) | H25: Videos >=500k | I25: Monetized?
B26: Weirdium | C26: 29200 | D26: 2026-02-22 | E26: 16.95 | F26: 329336 | G26: 1300000 | H26: 5 | I26: No
B27: SIMSKY BOSSKY | C27: 89900 | D27: 2026-03-27 | E27: 16.41 | F27: 1680737 | G27: 281000 | H27: 0 | I27: Yes
B28: Shadow Within Jung | C28: 10900 | D28: 2026-04-22 | E28: 13.87 | F28: 134718 | G28: 222000 | H28: 0 | I28: Yes
B29: Causality | C29: 17300 | D29: 2026-05-15 | E29: 9.47 | F29: 219269 | G29: 881000 | H29: 1 | I29: Yes
B30: Money Simplified | C30: 25300 | D30: 2026-02-05 | E30: 5.98 | F30: 119652 | G30: 596000 | H30: 1 | I30: No
B31: Humanity Timeline | C31: 3290 | D31: 2026-05-21 | E31: 5.26 | F31: 46980 | G31: 197000 | H31: 0 | I31: Yes
B32: You Are History | C32: 15700 | D32: 2026-03-01 | E32: 4.37 | F32: 256127 | G32: 1200000 | H32: 1 | I32: Yes
B33: Scribble History | C33: 1340 | D33: 2026-04-30 | E33: 4.24 | F33: 71786 | G33: 234000 | H33: 0 | I33: Yes
B34: Cornered. | C34: 4150 | D34: 2026-04-29 | E34: 3.84 | F34: 32652 | G34: 225000 | H34: 0 | I34: Yes
B35: Cruifan | C35: 3680 | D35: 2026-04-12 | E35: 3.19 | F35: 16783 | G35: 89000 | H35: 0 | I35: Yes
B36: The Geo Bytes | C36: 5070 | D36: 2026-04-09 | E36: 2.91 | F36: 38248 | G36: 271000 | H36: 0 | I36: No
B37: Inside Japan Living | C37: 25700 | D37: 2026-05-07 | E37: 2.77 | F37: 81210 | G37: 807000 | H37: 1 | I37: Yes
... B40: Bruce Lee Silent Power | C40: 5350 | D40: 2026-04-21 | E40: 2.53 | F40: 31755 | G40: 298000 | H40: 0 | I40: Yes
B43: Ancient Civilizations & Archaeology
B44: Channel | C44: Subscribers | D44: Created | E44: Outlier score | F44: Avg views/video | G44: Top video (views) | H44: Videos >=500k | I44: Monetized?
B45: Reddit Unseen Planet | C45: 2500 | D45: 2026-04-01 | E45: 44.98 | F45: 171454 | G45: 191000 | H45: 0 | I45: Yes
B46: Weirdium | C46: 29200 | D46: 2026-02-22 | E46: 16.95 | F46: 329336 | G46: 1300000 | H46: 5 | I46: No
B47: Immersive Bible Stories | C47: 35800 | D47: 2026-04-15 | E47: 10.12 | F47: 116583 | G47: 371000 | H47: 0 | I47: No
B48: Velkar Abyss Archive | C48: 5340 | D48: 2026-03-10 | E48: 9.24 | F48: 123052 | G48: 231000 | H48: 0 | I48: Yes
B49: Oldways Britain | C49: 2670 | D49: 2026-06-23 | E49: 5.5 | F49: 30557 | G49: 95000 | H49: 0 | I49: Yes
B50: Wildcrafted Homes | C50: 17400 | D50: 2026-02-11 | E50: 4.71 | F50: 325330 | G50: 3100000 | H50: 2 | I50: No
...
